const User = require('../models/User');

exports.getUsers = async (req, res) => {
  try {
    const users = await User.findAll();
    res.status(200).json(users);
  } catch (error) {
    res.status(500).json({ message: 'Error al obtener usuarios', error });
  }
};

exports.getUserById = async (req, res) => {
  try {
    const { id } = req.params;
    const user = await User.findByPk(id);
    if (!user) {
      return res.status(404).json({ message: 'Usuario no encontrado' });
    }
    res.status(200).json(user);
  } catch (error) {
    res.status(500).json({ message: 'Error al obtener el usuario', error });
  }
};

exports.updateUser = async (req, res) => {
  try {
    const { id } = req.params;
    const { firstName, lastName, email, phone } = req.body;

    const user = await User.findByPk(id);
    if (!user) {
      return res.status(404).json({ message: 'Usuario no encontrado' });
    }

    await user.update({ firstName, lastName, email, phone });
    res.status(200).json({ message: 'Usuario actualizado con éxito', user });
  } catch (error) {
    res.status(500).json({ message: 'Error al actualizar el usuario', error });
  }
};

exports.deleteUser = async (req, res) => {
  try {
    const { id } = req.params;

    const user = await User.findByPk(id);
    if (!user) {
      return res.status(404).json({ message: 'Usuario no encontrado' });
    }

    await user.destroy();
    res.status(200).json({ message: 'Usuario eliminado con éxito' });
  } catch (error) {
    res.status(500).json({ message: 'Error al eliminar el usuario', error });
  }
};

exports.getCurrentUser = async (req, res) => {
  try {
    const user = await User.findByPk(req.user.id, {
      attributes: ['id', 'firstName', 'lastName', 'email', 'phone', 'userType'], // Selecciona los campos necesarios
    });

    if (!user) {
      return res.status(404).json({ message: 'Usuario no encontrado' });
    }

    res.status(200).json(user);
  } catch (error) {
    console.error('Error al obtener el usuario:', error);
    res.status(500).json({ message: 'Error interno del servidor' });
  }
};